# 异步

众所周知，JS 是一门单线程语言，执行顺序是自上而下有序执行。

然后，当遇到需要较长时间来完成的操作时，比如加载文件、请求数据，通常这时候就会堵塞进程，只有等执行完这个操作之后，才能继续执行后续操作。

这样当然是不行的，本篇就来探究一下如何解决这个问题。

## 回调

我们先来定义一个需要一定时间才能完成的操作——加载 JS 文件

```js
function loadScript(src) {
  let script = document.createElement("script")
  script.src = src
  document.head.appendChild(script)
}
loadScript("https://cdn.jsdelivr.net/npm/jquery@3.2.1/dist/jquery.min.js") // 这是异步加载 jquery
console.log($) // 会先执行，会报错，$ is not defined
```

执行 loadScript 函数这个操作时，浏览器实际上在异步加载 script，同时跳到下一步执行其他操作。我们知道，JQuery 会暴露出来一个 \$ 对象，但是在这个例子中，抛出了错误，说明执行到这一步的时候，script 并没有加载完。如果我们需要在 script 加载完后执行操作，该怎么办呢，就需要用到 回调函数

```js
function loadScript(src, callBack) {
  let script = document.createElement("script")
  script.src = src
  script.onload = callBack
  document.head.appendChild(script)
}
loadScript("https://cdn.jsdelivr.net/npm/jquery@3.2.1/dist/jquery.min.js", function() {
  console.log($)
})
```

此时就可以正常在 script 加载完之后，执行某些操作了。

但是，当回调多了，嵌套就变得很多，从而出现回调地狱。为了解决这些问题，就出现了 Promise

## Promise

Promise 有三个状态，pending、fulfilled、rejected。初始状态为 pending，fulfilled 和 rejected 也统称为 settled

Promise 接收一个函数作为参数，函数接受 resolve, reject 两个回调，resolve 函数能将 promise 更改为 fulfilled，对应的 reject 则将 promise 更改为 rejected 状态。一个 promise 最终为 settled 状态的话，只能为 fulfilled 或者 rejected

```js
new Promise((resolve, reject) => {
  resolve(1) // 会将状态更改为 fulfilled
  reject("error")
})
```

Promise 还有三个方法 then、catch，finally

then 可以接收两个函数，第一个参数是状态为 fulfilled 时的回调，第二个参数为状态为 rejected 时的回调

catch 实际上是 then(null, fn )的语法糖，只关注错误时使用

finally 无论 promise 最终是何状态，最终都会执行

```js
new Promise((resolve, reject) => {
  resolve(1)
  reject("error")
})
  .then((res) => {
    console.log(res) // 为 resolve 函数的值，1
  })
  .catch((e) => {
    console.log(e) // 为 reject 的参数 'error'，当然，这个例子是不会打印的，因为 promise 的状态已经是 fulfilled 了
  })
  .finally(() => {
    // 都会执行
  })
```

## promise 链

then 和 catch 方法都会返回一个 promise

```js
new Promise((resolve, reject)=>{
  resolve(1)
})
.then(res => {
 res += 1
  rerurn res
})
.then(res => {
 console.log(res)  // 2
  throw new Error(res)
})
.catch(e => {
  console.warn(e)  // 2
})
```

then 方法 return 出来的值，会被下一个 then 方法接收，而如果方法中出现抛错，则会被 catch 捕获到
